2020-07-18 11:45:19,660: INFO: root: Starting main.py
2020-07-18 11:45:19,677: ERROR: root: 
Traceback (most recent call last):
  File "/mnt/d/Code Projects/telegram_bot_rpg/main.py", line 14, in <module>
    game = Game(game_db, telebot)
  File "/mnt/d/Code Projects/telegram_bot_rpg/Game.py", line 9, in __init__
    database.executeSqlQuery("CREATE TABLE IF NOT EXISTS Entity(entity_id INTEGER PRIMARY KEY AUTOINCREMENT, name TEXT, description TEXT, linked_entities INTEGER );")
  File "/mnt/d/Code Projects/telegram_bot_rpg/Database.py", line 12, in executeSqlQuery
    cursor.commit()
AttributeError: 'sqlite3.Cursor' object has no attribute 'commit'
2020-07-18 11:45:45,711: INFO: root: Starting main.py
2020-07-18 11:45:45,733: INFO: root: Done main.py
2020-07-18 11:45:51,361: INFO: root: Starting main.py
2020-07-18 11:45:51,383: INFO: root: Done main.py
2020-07-18 11:45:58,625: INFO: root: Starting main.py
2020-07-18 11:45:58,644: INFO: root: Done main.py
2020-07-18 11:45:59,429: INFO: root: Starting main.py
2020-07-18 11:45:59,448: INFO: root: Done main.py
2020-07-18 11:46:00,780: INFO: root: Starting main.py
2020-07-18 11:46:00,799: INFO: root: Done main.py
2020-07-18 11:47:00,453: INFO: root: Starting main.py
2020-07-18 11:47:00,764: INFO: root: Done main.py
2020-07-18 11:47:04,791: INFO: root: Starting main.py
2020-07-18 11:47:05,109: INFO: root: Done main.py
2020-07-18 11:47:12,379: INFO: root: Starting main.py
2020-07-18 11:47:12,669: INFO: root: Done main.py
2020-07-18 11:47:13,541: INFO: root: Starting main.py
2020-07-18 11:47:13,776: INFO: root: Done main.py
2020-07-18 11:51:19,430: INFO: root: Starting main.py
2020-07-18 11:51:19,449: INFO: root: Done main.py
2020-07-18 11:51:20,150: INFO: root: Starting main.py
2020-07-18 11:51:20,166: INFO: root: Done main.py
2020-07-18 11:51:24,897: INFO: root: Starting main.py
2020-07-18 11:51:24,915: INFO: root: Done main.py
2020-07-18 11:51:40,694: INFO: root: Starting main.py
2020-07-18 11:51:40,860: INFO: root: Done main.py
2020-07-18 11:51:45,314: INFO: root: Starting main.py
2020-07-18 11:51:45,486: INFO: root: Done main.py
2020-07-18 11:52:00,943: INFO: root: Starting main.py
2020-07-18 11:52:01,305: INFO: root: Done main.py
2020-07-18 12:30:42,781: INFO: root: Starting main.py
2020-07-18 12:30:42,797: INFO: root: Done main.py
2020-07-18 12:32:15,816: INFO: root: Starting main.py
2020-07-18 12:32:15,833: INFO: root: Done main.py
2020-07-18 12:33:00,533: INFO: root: Starting main.py
2020-07-18 12:33:00,548: ERROR: root: 
Traceback (most recent call last):
  File "/mnt/d/Code Projects/telegram_bot_rpg/main.py", line 14, in <module>
    game = Game(game_db, telebot)
  File "/mnt/d/Code Projects/telegram_bot_rpg/Game.py", line 13, in __init__
    database.createEntity("Training Room", "A room")
TypeError: createEntity() missing 1 required positional argument: 'linkedEntity_ids'
2020-07-18 12:33:01,739: INFO: root: Starting main.py
2020-07-18 12:33:01,752: ERROR: root: 
Traceback (most recent call last):
  File "/mnt/d/Code Projects/telegram_bot_rpg/main.py", line 14, in <module>
    game = Game(game_db, telebot)
  File "/mnt/d/Code Projects/telegram_bot_rpg/Game.py", line 13, in __init__
    database.createEntity("Training Room", "A room")
TypeError: createEntity() missing 1 required positional argument: 'linkedEntity_ids'
2020-07-18 12:33:27,366: INFO: root: Starting main.py
2020-07-18 12:33:27,385: ERROR: root: 
Traceback (most recent call last):
  File "/mnt/d/Code Projects/telegram_bot_rpg/main.py", line 14, in <module>
    game = Game(game_db, telebot)
  File "/mnt/d/Code Projects/telegram_bot_rpg/Game.py", line 13, in __init__
    database.createEntity("Training Room", "A room")
TypeError: createEntity() missing 1 required positional argument: 'linkedEntity_ids'
2020-07-18 12:33:33,462: INFO: root: Starting main.py
2020-07-18 12:33:33,479: ERROR: root: 
Traceback (most recent call last):
  File "/mnt/d/Code Projects/telegram_bot_rpg/main.py", line 14, in <module>
    game = Game(game_db, telebot)
  File "/mnt/d/Code Projects/telegram_bot_rpg/Game.py", line 13, in __init__
    database.createEntity("Training Room", "A room")
TypeError: createEntity() missing 1 required positional argument: 'linkedEntity_ids'
2020-07-18 12:33:34,310: INFO: root: Starting main.py
2020-07-18 12:33:34,325: ERROR: root: 
Traceback (most recent call last):
  File "/mnt/d/Code Projects/telegram_bot_rpg/main.py", line 14, in <module>
    game = Game(game_db, telebot)
  File "/mnt/d/Code Projects/telegram_bot_rpg/Game.py", line 13, in __init__
    database.createEntity("Training Room", "A room")
TypeError: createEntity() missing 1 required positional argument: 'linkedEntity_ids'
2020-07-18 12:33:34,954: INFO: root: Starting main.py
2020-07-18 12:33:34,971: ERROR: root: 
Traceback (most recent call last):
  File "/mnt/d/Code Projects/telegram_bot_rpg/main.py", line 14, in <module>
    game = Game(game_db, telebot)
  File "/mnt/d/Code Projects/telegram_bot_rpg/Game.py", line 13, in __init__
    database.createEntity("Training Room", "A room")
TypeError: createEntity() missing 1 required positional argument: 'linkedEntity_ids'
2020-07-18 12:33:35,570: INFO: root: Starting main.py
2020-07-18 12:33:35,582: ERROR: root: 
Traceback (most recent call last):
  File "/mnt/d/Code Projects/telegram_bot_rpg/main.py", line 14, in <module>
    game = Game(game_db, telebot)
  File "/mnt/d/Code Projects/telegram_bot_rpg/Game.py", line 13, in __init__
    database.createEntity("Training Room", "A room")
TypeError: createEntity() missing 1 required positional argument: 'linkedEntity_ids'
2020-07-18 12:33:55,428: INFO: root: Starting main.py
2020-07-18 12:33:55,446: ERROR: root: 
Traceback (most recent call last):
  File "/mnt/d/Code Projects/telegram_bot_rpg/main.py", line 14, in <module>
    game = Game(game_db, telebot)
  File "/mnt/d/Code Projects/telegram_bot_rpg/Game.py", line 13, in __init__
    database.createEntity("Training Room", "A room", None)
  File "/mnt/d/Code Projects/telegram_bot_rpg/Gamee/GameDatabase.py", line 38, in createEntity
    ent_list = self.createEntityList(linkedEntity_ids)
  File "/mnt/d/Code Projects/telegram_bot_rpg/Gamee/GameDatabase.py", line 48, in createEntityList
    for ent_id in linkedEntity_ids:
TypeError: 'NoneType' object is not iterable
2020-07-18 12:34:59,081: INFO: root: Starting main.py
2020-07-18 12:34:59,221: INFO: root: Done main.py
2020-07-18 12:36:35,859: INFO: root: Starting main.py
2020-07-18 12:36:36,060: INFO: root: Done main.py
2020-07-18 12:36:51,072: INFO: root: Starting main.py
2020-07-18 12:36:51,325: INFO: root: Done main.py
2020-07-18 12:37:52,805: INFO: root: Starting main.py
2020-07-18 12:37:53,043: ERROR: root: 
Traceback (most recent call last):
  File "/mnt/d/Code Projects/telegram_bot_rpg/main.py", line 14, in <module>
    game = Game(game_db, telebot)
  File "/mnt/d/Code Projects/telegram_bot_rpg/Game.py", line 14, in __init__
    print(database.getAllEntityLists())
AttributeError: 'GameDatabase' object has no attribute 'getAllEntityLists'
2020-07-18 12:38:07,158: INFO: root: Starting main.py
2020-07-18 12:38:07,462: ERROR: root: 
Traceback (most recent call last):
  File "/mnt/d/Code Projects/telegram_bot_rpg/main.py", line 14, in <module>
    game = Game(game_db, telebot)
  File "/mnt/d/Code Projects/telegram_bot_rpg/Game.py", line 14, in __init__
    print(database.getAllEntityLists())
AttributeError: 'GameDatabase' object has no attribute 'getAllEntityLists'
2020-07-18 12:38:20,921: INFO: root: Starting main.py
2020-07-18 12:38:21,195: INFO: root: Done main.py
2020-07-18 13:24:32,741: INFO: root: Starting main.py
2020-07-18 13:24:33,227: INFO: root: Done main.py
2020-07-18 13:25:41,123: INFO: root: Starting main.py
2020-07-18 13:25:41,356: INFO: root: Done main.py
2020-07-18 13:25:57,376: INFO: root: Starting main.py
2020-07-18 13:25:57,743: INFO: root: Done main.py
2020-07-18 13:26:13,393: INFO: root: Starting main.py
2020-07-18 13:26:13,819: INFO: root: Done main.py
2020-07-18 13:27:00,550: INFO: root: Starting main.py
2020-07-18 13:27:00,809: INFO: root: Done main.py
2020-07-18 13:27:15,812: INFO: root: Starting main.py
2020-07-18 13:27:16,086: INFO: root: Done main.py
2020-07-18 13:27:37,438: INFO: root: Starting main.py
2020-07-18 13:27:37,975: INFO: root: Done main.py
2020-07-18 13:27:53,046: INFO: root: Starting main.py
2020-07-18 13:27:53,506: INFO: root: Done main.py
2020-07-18 13:29:25,131: INFO: root: Starting main.py
2020-07-18 13:29:25,604: INFO: root: Done main.py
2020-07-18 13:43:47,177: INFO: root: Starting main.py
2020-07-18 13:43:47,713: ERROR: root: 
Traceback (most recent call last):
  File "/mnt/d/Code Projects/telegram_bot_rpg/main.py", line 14, in <module>
    game = Game(game_db, telebot)
  File "/mnt/d/Code Projects/telegram_bot_rpg/Game.py", line 15, in __init__
    listPersons = database.createEntity("Persons in Room", "")
TypeError: createEntity() missing 1 required positional argument: 'linkedEntity_ids'
2020-07-18 13:44:05,165: INFO: root: Starting main.py
2020-07-18 13:44:05,974: INFO: root: Done main.py
2020-07-18 13:45:00,036: INFO: root: Starting main.py
2020-07-18 13:45:00,813: ERROR: root: 
Traceback (most recent call last):
  File "/mnt/d/Code Projects/telegram_bot_rpg/main.py", line 14, in <module>
    game = Game(game_db, telebot)
  File "/mnt/d/Code Projects/telegram_bot_rpg/Game.py", line 21, in __init__
    print("EnL",database.getEntityList(3))
  File "/mnt/d/Code Projects/telegram_bot_rpg/Gamee/GameDatabase.py", line 69, in getEntityList
    cursor.execute(
ValueError: parameters are of unsupported type
2020-07-18 13:46:18,618: INFO: root: Starting main.py
2020-07-18 13:46:19,557: ERROR: root: 
Traceback (most recent call last):
  File "/mnt/d/Code Projects/telegram_bot_rpg/main.py", line 14, in <module>
    game = Game(game_db, telebot)
  File "/mnt/d/Code Projects/telegram_bot_rpg/Game.py", line 21, in __init__
    print("EnL",database.getEntityList(3))
  File "/mnt/d/Code Projects/telegram_bot_rpg/Gamee/GameDatabase.py", line 70, in getEntityList
    cursor.execute(
ValueError: parameters are of unsupported type
2020-07-18 13:46:28,064: INFO: root: Starting main.py
2020-07-18 13:46:28,861: ERROR: root: 
Traceback (most recent call last):
  File "/mnt/d/Code Projects/telegram_bot_rpg/main.py", line 14, in <module>
    game = Game(game_db, telebot)
  File "/mnt/d/Code Projects/telegram_bot_rpg/Game.py", line 21, in __init__
    print("EnL",database.getEntityList(3))
  File "/mnt/d/Code Projects/telegram_bot_rpg/Gamee/GameDatabase.py", line 70, in getEntityList
    cursor.execute(
ValueError: parameters are of unsupported type
2020-07-18 13:47:22,957: INFO: root: Starting main.py
2020-07-18 13:47:23,879: ERROR: root: 
Traceback (most recent call last):
  File "/mnt/d/Code Projects/telegram_bot_rpg/main.py", line 14, in <module>
    game = Game(game_db, telebot)
  File "/mnt/d/Code Projects/telegram_bot_rpg/Game.py", line 21, in __init__
    print("EnL",database.getEntityList(3))
  File "/mnt/d/Code Projects/telegram_bot_rpg/Gamee/GameDatabase.py", line 70, in getEntityList
    cursor.execute(
ValueError: parameters are of unsupported type
2020-07-18 13:47:44,829: INFO: root: Starting main.py
2020-07-18 13:47:45,628: ERROR: root: 
Traceback (most recent call last):
  File "/mnt/d/Code Projects/telegram_bot_rpg/main.py", line 14, in <module>
    game = Game(game_db, telebot)
  File "/mnt/d/Code Projects/telegram_bot_rpg/Game.py", line 21, in __init__
    print("EnL",database.getEntityList(3))
  File "/mnt/d/Code Projects/telegram_bot_rpg/Gamee/GameDatabase.py", line 70, in getEntityList
    cursor.execute(
sqlite3.InterfaceError: Error binding parameter 0 - probably unsupported type.
2020-07-18 13:48:12,211: INFO: root: Starting main.py
2020-07-18 13:48:12,983: ERROR: root: 
Traceback (most recent call last):
  File "/mnt/d/Code Projects/telegram_bot_rpg/main.py", line 14, in <module>
    game = Game(game_db, telebot)
  File "/mnt/d/Code Projects/telegram_bot_rpg/Game.py", line 21, in __init__
    print("EnL",database.getEntityList(3))
  File "/mnt/d/Code Projects/telegram_bot_rpg/Gamee/GameDatabase.py", line 70, in getEntityList
    cursor.execute(
sqlite3.InterfaceError: Error binding parameter 0 - probably unsupported type.
2020-07-18 13:49:06,882: INFO: root: Starting main.py
2020-07-18 13:49:07,828: ERROR: root: 
Traceback (most recent call last):
  File "/mnt/d/Code Projects/telegram_bot_rpg/main.py", line 14, in <module>
    game = Game(game_db, telebot)
  File "/mnt/d/Code Projects/telegram_bot_rpg/Game.py", line 21, in __init__
    print("EnL",database.getEntityList(3))
  File "/mnt/d/Code Projects/telegram_bot_rpg/Gamee/GameDatabase.py", line 70, in getEntityList
    cursor.execute(
sqlite3.InterfaceError: Error binding parameter 0 - probably unsupported type.
2020-07-18 13:50:26,274: INFO: root: Starting main.py
2020-07-18 13:50:27,226: ERROR: root: 
Traceback (most recent call last):
  File "/mnt/d/Code Projects/telegram_bot_rpg/main.py", line 14, in <module>
    game = Game(game_db, telebot)
  File "/mnt/d/Code Projects/telegram_bot_rpg/Game.py", line 21, in __init__
    print("EnL",database.getEntityList(3))
  File "/mnt/d/Code Projects/telegram_bot_rpg/Gamee/GameDatabase.py", line 74, in getEntityList
    out.append(answer[1])
IndexError: list index out of range
2020-07-18 13:50:59,684: INFO: root: Starting main.py
2020-07-18 13:51:00,425: ERROR: root: 
Traceback (most recent call last):
  File "/mnt/d/Code Projects/telegram_bot_rpg/main.py", line 14, in <module>
    game = Game(game_db, telebot)
  File "/mnt/d/Code Projects/telegram_bot_rpg/Game.py", line 21, in __init__
    print("EnL",database.getEntityList(3))
  File "/mnt/d/Code Projects/telegram_bot_rpg/Gamee/GameDatabase.py", line 75, in getEntityList
    out.append(answer[1])
IndexError: list index out of range
2020-07-18 13:51:15,202: INFO: root: Starting main.py
2020-07-18 13:51:16,115: INFO: root: Done main.py
2020-07-18 13:52:00,905: INFO: root: Starting main.py
2020-07-18 13:52:01,735: INFO: root: Done main.py
2020-07-18 14:12:15,272: INFO: root: Starting main.py
2020-07-18 14:12:16,241: INFO: root: Done main.py
2020-07-18 14:12:19,022: INFO: root: Starting main.py
2020-07-18 14:12:19,980: INFO: root: Done main.py
2020-07-18 14:12:29,898: INFO: root: Starting main.py
2020-07-18 14:12:30,851: INFO: root: Done main.py
2020-07-18 14:26:42,629: INFO: root: Starting main.py
2020-07-18 14:26:43,526: ERROR: root: 
Traceback (most recent call last):
  File "/mnt/d/Code Projects/telegram_bot_rpg/main.py", line 14, in <module>
    game = Game(game_db, telebot)
  File "/mnt/d/Code Projects/telegram_bot_rpg/Game.py", line 20, in __init__
    print("ale",database.getAllEntities())
  File "/mnt/d/Code Projects/telegram_bot_rpg/Gamee/GameDatabase.py", line 36, in getAllEntities
    return database.select("*","Entity")
TypeError: select() missing 1 required positional argument: 'where_condition'
2020-07-18 14:27:09,102: INFO: root: Starting main.py
2020-07-18 14:27:10,045: ERROR: root: 
Traceback (most recent call last):
  File "/mnt/d/Code Projects/telegram_bot_rpg/main.py", line 14, in <module>
    game = Game(game_db, telebot)
  File "/mnt/d/Code Projects/telegram_bot_rpg/Game.py", line 20, in __init__
    print("ale",database.getAllEntities())
  File "/mnt/d/Code Projects/telegram_bot_rpg/Gamee/GameDatabase.py", line 36, in getAllEntities
    return database.select("*","Entity")
  File "/mnt/d/Code Projects/telegram_bot_rpg/Database.py", line 24, in select
    cursor.execute("SELECT ? FROM ?",(cols,tablename))
sqlite3.OperationalError: near "?": syntax error
2020-07-18 14:29:04,197: INFO: root: Starting main.py
2020-07-18 14:29:05,180: ERROR: root: 
Traceback (most recent call last):
  File "/mnt/d/Code Projects/telegram_bot_rpg/main.py", line 14, in <module>
    game = Game(game_db, telebot)
  File "/mnt/d/Code Projects/telegram_bot_rpg/Game.py", line 20, in __init__
    print("ale",database.getAllEntities())
  File "/mnt/d/Code Projects/telegram_bot_rpg/Gamee/GameDatabase.py", line 36, in getAllEntities
    return database.selectUnsafe("*","Entity")
  File "/mnt/d/Code Projects/telegram_bot_rpg/Database.py", line 24, in selectUnsafe
    cursor.execute("SELECT {cols} FROM {tablename}")
sqlite3.OperationalError: unrecognized token: "{"
2020-07-18 14:29:57,575: INFO: root: Starting main.py
2020-07-18 14:29:58,596: INFO: root: Done main.py
2020-07-18 14:30:32,008: INFO: root: Starting main.py
2020-07-18 14:30:32,909: INFO: root: Done main.py
2020-07-18 14:31:11,242: INFO: root: Starting main.py
2020-07-18 14:31:12,041: ERROR: root: 
Traceback (most recent call last):
  File "/mnt/d/Code Projects/telegram_bot_rpg/main.py", line 14, in <module>
    game = Game(game_db, telebot)
  File "/mnt/d/Code Projects/telegram_bot_rpg/Game.py", line 20, in __init__
    print("ale",database.getAllEntities())
  File "/mnt/d/Code Projects/telegram_bot_rpg/Gamee/GameDatabase.py", line 36, in getAllEntities
    return database.selectUnsafe("*","Entity")
  File "/mnt/d/Code Projects/telegram_bot_rpg/Database.py", line 24, in selectUnsafe
    cursor.execute("SELECT %s FROM ?"%(cols),(tablename,))
sqlite3.OperationalError: near "?": syntax error
2020-07-18 14:36:49,007: INFO: root: Starting main.py
2020-07-18 14:36:49,850: INFO: root: Done main.py
